<?xml version="1.0" ?>
<robot name="palletron_gazebo" xmlns:xacro="http://ros.org/wiki/xacro">
  <material name="black">
      <color rgba="0.0 0.0 0.0 1.0"/>
  </material>

  <material name="dark">
    <color rgba="0.3 0.3 0.3 1.0"/>
  </material>

  <material name="light_black">
    <color rgba="0.4 0.4 0.4 1.0"/>
  </material>

  <material name="blue">
    <color rgba="0.0 0.0 0.8 1.0"/>
  </material>

  <material name="green">
    <color rgba="0.0 0.8 0.0 1.0"/>
  </material>

  <material name="grey">
    <color rgba="0.5 0.5 0.5 1.0"/>
  </material>

  <material name="orange">
    <color rgba="1.0 0.4235 0.0392 1.0"/>
  </material>

  <material name="brown">
    <color rgba="0.8706 0.8118 0.7647 1.0"/>
  </material>

  <material name="red">
    <color rgba="0.8 0.0 0.0 1.0"/>
  </material>

  <material name="white">
    <color rgba="1.0 1.0 1.0 1.0"/>
  </material>

  <link name="base_footprint"/>
    
  <joint name="base_joint" type="fixed">
    <parent link="base_footprint"/>
    <child link="base_link" />
    <origin xyz="0 0 0.13" rpy="0 0 0"/>
  </joint>
    
  <link name="base_link">
    <visual>
      <origin xyz="0 0 0.04" rpy="0 0 0"/>
      <geometry>
        <cylinder length="0.2" radius="0.3"/>
      </geometry>
    </visual>

    <collision>
      <origin xyz="0 0 0.04" rpy="0 0 0"/>
      <geometry>
        <cylinder length="0.2" radius="0.3"/>
      </geometry>
    </collision>

    <!-- TODO: update according to real base properties -->
    <inertial>
      <origin xyz="-0.00000106 0.00000109 0.0000387" rpy="0 0 0"/>
      <mass value="15.0"/>
      <inertia ixx="0.465408937" ixy="0.002160024" ixz="-0.001760255"
               iyy="0.483193291" iyz="-0.000655952"
               izz="0.550939703"/>
    </inertial>
  </link>
  
  <joint name="wheel_left_joint" type="continuous">
    <origin xyz="0 0.325 0" rpy="-1.57 0 0"/>
    <parent link="base_link"/>
    <child link="wheel_left_link"/>
    <axis xyz="0 0 1"/>
  </joint>

  <link name="wheel_left_link">
    <visual>
      <origin xyz="0 0 0" rpy="0 0 0"/>
      <geometry>
        <cylinder radius="0.13" length="0.05"/>
      </geometry>
      <material name="dark"/>
    </visual>

    <collision>
      <origin xyz="0 0 0" rpy="0 0 0"/>
      <geometry>
        <cylinder radius="0.13" length="0.05"/>
      </geometry>
    </collision>

    <inertial>
      <origin xyz="0 0 0.00207" rpy="0 0 0"/>
      <!-- TODO: update according to real wheel properties -->
      <mass value="1.0"/>
      <inertia ixx="0.00499743171" ixy="-0.00000004464" ixz="-0.00000002245"
               iyy="0.00499741733" iyz="0.00000000164"
               izz="0.00839239692"/>
    </inertial>
  </link>

  <joint name="wheel_right_joint" type="continuous">
    <origin xyz="0 -0.325 0" rpy="-1.57 0 0"/>
    <parent link="base_link"/>
    <child link="wheel_right_link"/>
    <axis xyz="0 0 1"/>
  </joint>

  <link name="wheel_right_link">
    <visual>
      <origin xyz="0 0 0" rpy="0 0 0"/>
      <geometry>
        <cylinder radius="0.13" length="0.05"/>
      </geometry>
      <material name="dark"/>
    </visual>

    <collision>
      <origin xyz="0 0 0" rpy="0 0 0"/>
      <geometry>
        <cylinder radius="0.13" length="0.05"/>
      </geometry>
    </collision>

    <inertial>
      <origin xyz="0 0 -0.00207" rpy="0 0 0"/>
      <!-- TODO: update according to real wheel properties -->
      <mass value="1.0"/>
      <inertia ixx="0.00499743171" ixy="0.00000004464" ixz="-0.00000002245"
               iyy="0.00499741733" iyz="-0.00000000164"
               izz="0.00839239692"/>
    </inertial>
  </link>

  <plugin name="palletron_diff_drive" filename="libgazebo_ros_diff_drive.so">
    <ros>
      <!--since gazebo_plugins publish tf topic in global namespace /tf only and it
        cannot be remapped like (namespace/tf) through launch arguments -->
      <remapping>/tf:=tf</remapping>
    </ros>

    <update_rate>30</update_rate>

    <!-- wheels -->
    <left_joint>wheel_left_joint</left_joint>
    <right_joint>wheel_right_joint</right_joint>

    <!-- kinematics -->
    <wheel_separation>0.287</wheel_separation>
    <wheel_diameter>0.066</wheel_diameter>

    <!-- limits -->
    <max_wheel_torque>20</max_wheel_torque>
    <max_wheel_acceleration>1.0</max_wheel_acceleration>

    <command_topic>cmd_vel</command_topic>

    <!-- output -->
    <publish_odom>true</publish_odom>
    <publish_odom_tf>true</publish_odom_tf>
    <publish_wheel_tf>false</publish_wheel_tf>

    <odometry_topic>odom</odometry_topic>
    <odometry_frame>odom</odometry_frame>
    <robot_base_frame>base_footprint</robot_base_frame>
  </plugin>

  <plugin name="palletron_joint_state" filename="libgazebo_ros_joint_state_publisher.so">
    <ros>
      <remapping>~/out:=joint_states</remapping>
    </ros>
    <update_rate>30</update_rate>
    <joint_name>wheel_left_joint</joint_name>
    <joint_name>wheel_right_joint</joint_name>
  </plugin>
  
  <gazebo reference="base_link">
    <material>Gazebo/Blue</material>
  </gazebo>
</robot>
