<?xml version="1.0" ?>
<robot name="palletron" xmlns:xacro="http://ros.org/wiki/xacro">
  <material name="black">
      <color rgba="0.0 0.0 0.0 1.0"/>
  </material>

  <material name="dark">
    <color rgba="0.3 0.3 0.3 1.0"/>
  </material>

  <material name="light_black">
    <color rgba="0.4 0.4 0.4 1.0"/>
  </material>

  <material name="blue">
    <color rgba="0.0 0.0 0.8 1.0"/>
  </material>

  <material name="green">
    <color rgba="0.0 0.8 0.0 1.0"/>
  </material>

  <material name="grey">
    <color rgba="0.5 0.5 0.5 1.0"/>
  </material>

  <material name="orange">
    <color rgba="1.0 0.4235 0.0392 1.0"/>
  </material>

  <material name="brown">
    <color rgba="0.8706 0.8118 0.7647 1.0"/>
  </material>

  <material name="red">
    <color rgba="0.8 0.0 0.0 1.0"/>
  </material>

  <material name="white">
    <color rgba="1.0 1.0 1.0 1.0"/>
  </material>

  <link name="base_footprint"/>

  <joint name="base_joint" type="fixed">
    <parent link="base_footprint"/>
    <child link="base_link" />
    <origin xyz="0 0 0.13" rpy="0 0 0"/>
  </joint>

  <link name="base_link">
    <visual>
      <origin xyz="0 0 0.04" rpy="0 0 0"/>
      <geometry>
        <cylinder length="0.2" radius="0.3"/>
      </geometry>
      <material name="blue"/>
    </visual>

    <collision>
      <origin xyz="0 0 0.04" rpy="0 0 0"/>
      <geometry>
        <cylinder length="0.2" radius="0.3"/>
      </geometry>
    </collision>

    <!-- TODO: update according to real base properties -->
    <inertial>
      <origin xyz="-0.00000106 0.00000109 0.0000387" rpy="0 0 0"/>
      <mass value="15.0"/>
      <inertia ixx="0.465408937" ixy="0.002160024" ixz="-0.001760255"
               iyy="0.483193291" iyz="-0.000655952"
               izz="0.550939703"/>
    </inertial>
  </link>

  <joint name="wheel_left_joint" type="continuous">
    <origin xyz="0 0.325 0" rpy="-1.57 0 0"/>
    <parent link="base_link"/>
    <child link="wheel_left_link"/>
    <axis xyz="0 0 1"/>
  </joint>

  <link name="wheel_left_link">
    <visual>
      <origin xyz="0 0 0" rpy="0 0 0"/>
      <geometry>
        <cylinder radius="0.13" length="0.05"/>
      </geometry>
      <material name="dark"/>
    </visual>

    <collision>
      <origin xyz="0 0 0" rpy="0 0 0"/>
      <geometry>
        <cylinder radius="0.13" length="0.05"/>
      </geometry>
    </collision>

    <inertial>
      <origin xyz="0 0 0.00207" rpy="0 0 0"/>
      <!-- TODO: update according to real wheel properties -->
      <mass value="1.0"/>
      <inertia ixx="0.00499743171" ixy="-0.00000004464" ixz="-0.00000002245"
               iyy="0.00499741733" iyz="0.00000000164"
               izz="0.00839239692"/>
    </inertial>
  </link>

  <joint name="wheel_right_joint" type="continuous">
    <origin xyz="0 -0.325 0" rpy="-1.57 0 0"/>
    <parent link="base_link"/>
    <child link="wheel_right_link"/>
    <axis xyz="0 0 1"/>
  </joint>

  <link name="wheel_right_link">
    <visual>
      <origin xyz="0 0 0" rpy="0 0 0"/>
      <geometry>
        <cylinder radius="0.13" length="0.05"/>
      </geometry>
      <material name="dark"/>
    </visual>

    <collision>
      <origin xyz="0 0 0" rpy="0 0 0"/>
      <geometry>
        <cylinder radius="0.13" length="0.05"/>
      </geometry>
    </collision>

    <inertial>
      <origin xyz="0 0 -0.00207" rpy="0 0 0"/>
      <!-- TODO: update according to real wheel properties -->
      <mass value="1.0"/>
      <inertia ixx="0.00499743171" ixy="0.00000004464" ixz="-0.00000002245"
               iyy="0.00499741733" iyz="-0.00000000164"
               izz="0.00839239692"/>
    </inertial>
  </link>
</robot>
